Workbook

Sheet Nates Projections
A1: To use this sheet, you will need to make a copy first to be able to edit (File -> Make a copy). Enter "Yes" if the category is used in your league or "No" if it is not in the "Category Used?" row. Then use the "Weight" row to assign a points weight to each category. You only need to enter information into the cells highlighted in red. The rows highlighted in green will output the total number of projected Fantasy Points and the projected Fantasy Points per game played for your league. | P1: Selections for VORP / Positional Eligibility / Off-Nights Effects | AD1: VORP F Number | AE1: VORP D Number
P2: VORP On? | R2: Positional Eligibility | U2: Off-Nights Effects | X2: # of Teams | Z2: # of Starting F | AA2: # of Starting D | AC2: Rank | AD2: =X3*Z3 -> 120 | AE2: =X3*AA3 -> 48
P3: Yes | R3: Medium Effect | U3: Medium Effect | X3: 12 | Z3: 10 | AA3: 4 | AC3: FPts per GP | AD3: =VLOOKUP(AD2,CALC!$Y$3:$AA$494,2,FALSE) -> 5.7566071 | AE3: =VLOOKUP(AE2,CALC!$Y$3:$AA$494,3,FALSE) -> 4.914619
A4: Category Used? Yes/No | F4: Yes | G4: Yes | H4: Yes | I4: Yes | J4: Yes | K4: Yes | L4: Yes | M4: Yes | N4: Yes | O4: Yes | P4: All numbers below in these columns are generated automatically by the spreadsheet
A5: Weight | F5: 5 | G5: 3.75 | H5: 1 | I5: 0.5 | J5: 0.5 | K5: 0.3 | L5: 0.6 | M5: 1 | N5: 1 | O5: 0
A6: Player | B6: Info | E6: Projections - Nate
A7: Name | B7: Team | C7: Y! Pos | D7: Proj PP | E7: GP | F7: G | G7: A | H7: PTS | I7: PPP | J7: SOG | K7: HIT | L7: BLK | M7: PIM | N7: S% | O7: ATOI | P7: G | Q7: A | R7: PTS | S7: PPP | T7: SOG | U7: HIT | V7: BLK | W7: PIM | X7: S% | Y7: ATOI | Z7: FPTS - Total | AA7: FPTS per GP | AB7: =IF(AND(P3="Yes",R3="Full Effect",U3="Full Effect"),AJ7,IF(AND(P3="Yes",R3="Medium Effect",U3="Full Effect"),AJ7,IF(AND(P3="Yes",R3="Full Effect",U3="Medium Effect"),AJ7,IF(AND(P3="Yes",R3="Medium Effect",U3="Medium Effect"),AJ7,IF(AND(P3="Yes",R3="No Effect",U3="Medium Effect"),AI7,IF(AND(P3="Yes",R3="No Effect",U3="Full Effect"),AI7,IF(AND(P3="Yes",R3="Medium Effect",U3="No Effect"),AH7,IF(AND(P3="Yes",R3="Full Effect",U3="No Effect"),AH7,IF(AND(P3="No",R3="Full Effect",U3="Full Effect"),AF7,IF(AND(P3="No",R3="Medium Effect",U3="Full Effect"),AF7,IF(AND(P3="No",R3="Full Effect",U3="Medium Effect"),AF7,IF(AND(P3="No",R3="Medium Effect",U3="Medium Effect"),AF7,IF(AND(P3="No",R3="No Effect",U3="Medium Effect"),AE7,IF(AND(P3="No",R3="No Effect",U3="Full Effect"),AE7,IF(AND(P3="No",R3="Medium Effect",U3="No Effect"),AD7,IF(AND(P3="No",R3="Full Effect",U3="No Effect"),AD7,IF(AND(P3="Yes",R3="No Effect",U3="No Effect"),AG7,"No Change"))))))))))))))))) -> VORP + PE + ONE | AD7: FPts per GP + PE | AE7: FPts per GP + ONE | AF7: FPts per GP + PE + ONE | AG7: VORP | AH7: VORP + PE | AI7: VORP + ONE | AJ7: VORP + PE + ONE | AL7: Full Pos | AM7: Med Pos | AN7: Full Off | AO7: Med Off | AQ7: FPts per GP + MPE | AR7: FPts per GP + FPE | AS7: FPts per GP + MONE | AT7: FPts per GP + FONE | AU7: FPts per GP + MPE + MONE | AV7: FPts per GP + MPE + FONE | AW7: FPts per GP + FPE + MONE | AX7: FPts per GP + FPE + FONE | AY7: VORP | AZ7: VORP + MPE | BA7: VORP + FPE | BB7: VORP + MONE | BC7: VORP + FONE | BD7: VORP + MPE + MONE | BE7: VORP + MPE + FONE | BF7: VORP + FPE + MONE | BG7: VORP + FPE + FONE
A8: Nathan Mackinnon | B8: COL | C8: =VLOOKUP(A8,CALC!$A$2:$C$494,3,FALSE) -> C | D8: 1 | E8: 84 | F8: 45.3 | G8: 83.7 | H8: 129.1 | I8: 35.7 | J8: 359.8 | K8: 58.1 | L8: 44.1 | M8: 30.8 | N8: 0.126 | O8: 22 | P8: =IF(F$4="Yes",F8*F$5,0) -> 226.5 | Q8: =IF(G$4="Yes",G8*G$5,0) -> 313.875 | R8: =IF(H$4="Yes",H8*H$5,0) -> 129.1 | S8: =IF(I$4="Yes",I8*I$5,0) -> 17.85 | T8: =IF(J$4="Yes",J8*J$5,0) -> 179.9 | U8: =IF(K$4="Yes",K8*K$5,0) -> 17.43 | V8: =IF(L$4="Yes",L8*L$5,0) -> 26.46 | W8: =IF(M$4="Yes",M8*M$5,0) -> 30.8 | ... Y8: =IF(O$4="Yes",O8*O$5,0) -> 0 | Z8: =SUM(P8:Y8) -> 942.041 | AA8: =Z8/E8 -> 11.214774 | AB8: =IF(AND($P$3="Yes",$R$3="Full Effect",$U$3="Full Effect"),$BG8,IF(AND($P$3="Yes",$R$3="Medium Effect",$U$3="Full Effect"),$BE8,IF(AND($P$3="Yes",$R$3="Full Effect",$U$3="Medium Effect"),$BF8,IF(AND($P$3="Yes",$R$3="Medium Effect",$U$3="Medium Effect"),$BD8,IF(AND($P$3="Yes",$R$3="No Effect",$U$3="Medium Effect"),$BB8,IF(AND($P$3="Yes",$R$3="No Effect",$U$3="Full Effect"),$BC8,IF(AND($P$3="Yes",$R$3="Medium Effect",$U$3="No Effect"),$AZ8,IF(AND($P$3="Yes",$R$3="Full Effect",$U$3="No Effect"),$BA8,IF(AND($P$3="No",$R$3="Full Effect",$U$3="Full Effect"),$AX8,IF(AND($P$3="No",$R$3="Medium Effect",$U$3="Full Effect"),$AV8,IF(AND($P$3="No",$R$3="Full Effect",$U$3="Medium Effect"),$AW8,IF(AND($P$3="No",$R$3="Medium Effect",$U$3="Medium Effect"),$AU8,IF(AND($P$3="No",$R$3="No Effect",$U$3="Medium Effect"),$AS8,IF(AND($P$3="No",$R$3="No Effect",$U$3="Full Effect"),$AT8,IF(AND($P$3="No",$R$3="Medium Effect",$U$3="No Effect"),$AQ8,IF(AND($P$3="No",$R$3="Full Effect",$U$3="No Effect"),$AR8,IF(AND($P3="Yes",$R$3="No Effect",$U$3="No Effect"),$AY8,"Use FPTS per GP"))))))))))))))))) -> 5.7234336 | AL8: =IFERROR(VLOOKUP(C8,CALC!$K$2:$M$8,2,FALSE),1) -> 0.96 | AM8: =IFERROR(VLOOKUP(C8,CALC!$K$2:$M$8,3,FALSE),1) -> 0.98 | AN8: =VLOOKUP(B8,CALC!$E$2:$H$33,3,FALSE) -> 1.14 | AO8: =VLOOKUP(B8,CALC!$E$2:$H$33,4,FALSE) -> 1.07 | AQ8: =$AA8*AM8 -> 10.990478 | AR8: =$AA8*AL8 -> 10.766183 | AS8: =$AA8*AO8 -> 11.999808 | AT8: =$AA8*AN8 -> 12.784842 | AU8: =$AA8*AM8*AO8 -> 11.759812 | AV8: =$AA8*AM8*AN8 -> 12.529145 | AW8: =$AA8*AL8*AO8 -> 11.519816 | AX8: =$AA8*AL8*AN8 -> 12.273448 | AY8: =IF($C8="D",$AA8-$AE$3,$AA8-$AD$3) -> 5.4581667 | AZ8: =$AY8*AM8 -> 5.3490033 | BA8: =$AY8*AL8 -> 5.23984 | BB8: =$AY8*AO8 -> 5.8402383 | BC8: =$AY8*AN8 -> 6.22231 | BD8: =$AY8*AM8*AO8 -> 5.7234336 | BE8: =$AY8*AM8*AN8 -> 6.0978638 | BF8: =$AY8*AL8*AO8 -> 5.6066288 | BG8: =$AY8*AL8*AN8 -> 5.9734176
A9: Connor McDavid | B9: EDM | C9: =VLOOKUP(A9,CALC!$A$2:$C$494,3,FALSE) -> C | D9: 1 | E9: 84 | F9: 43.4 | G9: 88 | H9: 131.5 | I9: 48.5 | J9: 286.3 | K9: 53.4 | L9: 28.4 | M9: 36.9 | N9: 0.152 | O9: 22 | P9: =IF(F$4="Yes",F9*F$5,0) -> 217 | Q9: =IF(G$4="Yes",G9*G$5,0) -> 330 | R9: =IF(H$4="Yes",H9*H$5,0) -> 131.5 | S9: =IF(I$4="Yes",I9*I$5,0) -> 24.25 | T9: =IF(J$4="Yes",J9*J$5,0) -> 143.15 | U9: =IF(K$4="Yes",K9*K$5,0) -> 16.02 | V9: =IF(L$4="Yes",L9*L$5,0) -> 17.04 | W9: =IF(M$4="Yes",M9*M$5,0) -> 36.9 | ... Y9: =IF(O$4="Yes",O9*O$5,0) -> 0 | Z9: =SUM(P9:Y9) -> 916.012 | AA9: =Z9/E9 -> 10.904905 | AB9: =IF(AND($P$3="Yes",$R$3="Full Effect",$U$3="Full Effect"),$BG9,IF(AND($P$3="Yes",$R$3="Medium Effect",$U$3="Full Effect"),$BE9,IF(AND($P$3="Yes",$R$3="Full Effect",$U$3="Medium Effect"),$BF9,IF(AND($P$3="Yes",$R$3="Medium Effect",$U$3="Medium Effect"),$BD9,IF(AND($P$3="Yes",$R$3="No Effect",$U$3="Medium Effect"),$BB9,IF(AND($P$3="Yes",$R$3="No Effect",$U$3="Full Effect"),$BC9,IF(AND($P$3="Yes",$R$3="Medium Effect",$U$3="No Effect"),$AZ9,IF(AND($P$3="Yes",$R$3="Full Effect",$U$3="No Effect"),$BA9,IF(AND($P$3="No",$R$3="Full Effect",$U$3="Full Effect"),$AX9,IF(AND($P$3="No",$R$3="Medium Effect",$U$3="Full Effect"),$AV9,IF(AND($P$3="No",$R$3="Full Effect",$U$3="Medium Effect"),$AW9,IF(AND($P$3="No",$R$3="Medium Effect",$U$3="Medium Effect"),$AU9,IF(AND($P$3="No",$R$3="No Effect",$U$3="Medium Effect"),$AS9,IF(AND($P$3="No",$R$3="No Effect",$U$3="Full Effect"),$AT9,IF(AND($P$3="No",$R$3="Medium Effect",$U$3="No Effect"),$AQ9,IF(AND($P$3="No",$R$3="Full Effect",$U$3="No Effect"),$AR9,IF(AND($P4="Yes",$R$3="No Effect",$U$3="No Effect"),$AY9,"Use FPTS per GP"))))))))))))))))) -> 5.2723716 | AL9: =IFERROR(VLOOKUP(C9,CALC!$K$2:$M$8,2,FALSE),1) -> 0.96 | AM9: =IFERROR(VLOOKUP(C9,CALC!$K$2:$M$8,3,FALSE),1) -> 0.98 | AN9: =VLOOKUP(B9,CALC!$E$2:$H$33,3,FALSE) -> 1.09 | AO9: =VLOOKUP(B9,CALC!$E$2:$H$33,4,FALSE) -> 1.045 | AQ9: =$AA9*AM9 -> 10.686807 | AR9: =$AA9*AL9 -> 10.468709 | AS9: =$AA9*AO9 -> 11.395625 | AT9: =$AA9*AN9 -> 11.886346 | AU9: =$AA9*AM9*AO9 -> 11.167713 | AV9: =$AA9*AM9*AN9 -> 11.648619 | AW9: =$AA9*AL9*AO9 -> 10.9398 | AX9: =$AA9*AL9*AN9 -> 11.410892 | AY9: =IF($C9="D",$AA9-$AE$3,$AA9-$AD$3) -> 5.1482976 | AZ9: =$AY9*AM9 -> 5.0453317 | BA9: =$AY9*AL9 -> 4.9423657 | BB9: =$AY9*AO9 -> 5.379971 | BC9: =$AY9*AN9 -> 5.6116444 | BD9: =$AY9*AM9*AO9 -> 5.2723716 | BE9: =$AY9*AM9*AN9 -> 5.4994115 | BF9: =$AY9*AL9*AO9 -> 5.1647722 | BG9: =$AY9*AL9*AN9 -> 5.3871786
A10: Nikita Kucherov | B10: TBL | C10: =VLOOKUP(A10,CALC!$A$2:$C$494,3,FALSE) -> RW | D10: 1 | E10: 84 | F10: 41.8 | G10: 88.8 | H10: 130.6 | I10: 40.9 | J10: 255 | K10: 31.8 | L10: 32.4 | M10: 48.6 | N10: 0.164 | O10: 20.25 | P10: =IF(F$4="Yes",F10*F$5,0) -> 209 | Q10: =IF(G$4="Yes",G10*G$5,0) -> 333 | R10: =IF(H$4="Yes",H10*H$5,0) -> 130.6 | S10: =IF(I$4="Yes",I10*I$5,0) -> 20.45 | T10: =IF(J$4="Yes",J10*J$5,0) -> 127.5 | U10: =IF(K$4="Yes",K10*K$5,0) -> 9.54 | V10: =IF(L$4="Yes",L10*L$5,0) -> 19.44 | W10: =IF(M$4="Yes",M10*M$5,0) -> 48.6 | ... Y10: =IF(O$4="Yes",O10*O$5,0) -> 0 | Z10: =SUM(P10:Y10) -> 898.294 | AA10: =Z10/E10 -> 10.693976 | AB10: =IF(AND($P$3="Yes",$R$3="Full Effect",$U$3="Full Effect"),$BG10,IF(AND($P$3="Yes",$R$3="Medium Effect",$U$3="Full Effect"),$BE10,IF(AND($P$3="Yes",$R$3="Full Effect",$U$3="Medium Effect"),$BF10,IF(AND($P$3="Yes",$R$3="Medium Effect",$U$3="Medium Effect"),$BD10,IF(AND($P$3="Yes",$R$3="No Effect",$U$3="Medium Effect"),$BB10,IF(AND($P$3="Yes",$R$3="No Effect",$U$3="Full Effect"),$BC10,IF(AND($P$3="Yes",$R$3="Medium Effect",$U$3="No Effect"),$AZ10,IF(AND($P$3="Yes",$R$3="Full Effect",$U$3="No Effect"),$BA10,IF(AND($P$3="No",$R$3="Full Effect",$U$3="Full Effect"),$AX10,IF(AND($P$3="No",$R$3="Medium Effect",$U$3="Full Effect"),$AV10,IF(AND($P$3="No",$R$3="Full Effect",$U$3="Medium Effect"),$AW10,IF(AND($P$3="No",$R$3="Medium Effect",$U$3="Medium Effect"),$AU10,IF(AND($P$3="No",$R$3="No Effect",$U$3="Medium Effect"),$AS10,IF(AND($P$3="No",$R$3="No Effect",$U$3="Full Effect"),$AT10,IF(AND($P$3="No",$R$3="Medium Effect",$U$3="No Effect"),$AQ10,IF(AND($P$3="No",$R$3="Full Effect",$U$3="No Effect"),$AR10,IF(AND($P5="Yes",$R$3="No Effect",$U$3="No Effect"),$AY10,"Use FPTS per GP"))))))))))))))))) -> 4.4047504 | AL10: =IFERROR(VLOOKUP(C10,CALC!$K$2:$M$8,2,FALSE),1) -> 0.95 | AM10: =IFERROR(VLOOKUP(C10,CALC!$K$2:$M$8,3,FALSE),1) -> 0.975 | AN10: =VLOOKUP(B10,CALC!$E$2:$H$33,3,FALSE) -> 0.83 | AO10: =VLOOKUP(B10,CALC!$E$2:$H$33,4,FALSE) -> 0.915 | AQ10: =$AA10*AM10 -> 10.426627 | AR10: =$AA10*AL10 -> 10.159277 | AS10: =$AA10*AO10 -> 9.7849882 | AT10: =$AA10*AN10 -> 8.8760002 | AU10: =$AA10*AM10*AO10 -> 9.5403635 | AV10: =$AA10*AM10*AN10 -> 8.6541002 | AW10: =$AA10*AL10*AO10 -> 9.2957388 | AX10: =$AA10*AL10*AN10 -> 8.4322002 | AY10: =IF($C10="D",$AA10-$AE$3,$AA10-$AD$3) -> 4.937369 | AZ10: =$AY10*AM10 -> 4.8139348 | BA10: =$AY10*AL10 -> 4.6905006 | BB10: =$AY10*AO10 -> 4.5176927 | BC10: =$AY10*AN10 -> 4.0980163 | BD10: =$AY10*AM10*AO10 -> 4.4047504 | BE10: =$AY10*AM10*AN10 -> 3.9955659 | BF10: =$AY10*AL10*AO10 -> 4.291808 | BG10: =$AY10*AL10*AN10 -> 3.8931155
A11: Macklin Celebrini | B11: SJS | C11: =VLOOKUP(A11,CALC!$A$2:$C$494,3,FALSE) -> C | D11: 1 | E11: 84 | F11: 48.3 | G11: 65.2 | H11: 113.5 | I11: 36.5 | J11: 299.8 | K11: 52.7 | L11: 55.9 | M11: 42.5 | N11: 0.161 | O11: 21.5 | P11: =IF(F$4="Yes",F11*F$5,0) -> 241.5 | Q11: =IF(G$4="Yes",G11*G$5,0) -> 244.5 | R11: =IF(H$4="Yes",H11*H$5,0) -> 113.5 | S11: =IF(I$4="Yes",I11*I$5,0) -> 18.25 | T11: =IF(J$4="Yes",J11*J$5,0) -> 149.9 | U11: =IF(K$4="Yes",K11*K$5,0) -> 15.81 | V11: =IF(L$4="Yes",L11*L$5,0) -> 33.54 | W11: =IF(M$4="Yes",M11*M$5,0) -> 42.5 | ... Y11: =IF(O$4="Yes",O11*O$5,0) -> 0 | Z11: =SUM(P11:Y11) -> 859.661 | AA11: =Z11/E11 -> 10.23406 | AB11: =IF(AND($P$3="Yes",$R$3="Full Effect",$U$3="Full Effect"),$BG11,IF(AND($P$3="Yes",$R$3="Medium Effect",$U$3="Full Effect"),$BE11,IF(AND($P$3="Yes",$R$3="Full Effect",$U$3="Medium Effect"),$BF11,IF(AND($P$3="Yes",$R$3="Medium Effect",$U$3="Medium Effect"),$BD11,IF(AND($P$3="Yes",$R$3="No Effect",$U$3="Medium Effect"),$BB11,IF(AND($P$3="Yes",$R$3="No Effect",$U$3="Full Effect"),$BC11,IF(AND($P$3="Yes",$R$3="Medium Effect",$U$3="No Effect"),$AZ11,IF(AND($P$3="Yes",$R$3="Full Effect",$U$3="No Effect"),$BA11,IF(AND($P$3="No",$R$3="Full Effect",$U$3="Full Effect"),$AX11,IF(AND($P$3="No",$R$3="Medium Effect",$U$3="Full Effect"),$AV11,IF(AND($P$3="No",$R$3="Full Effect",$U$3="Medium Effect"),$AW11,IF(AND($P$3="No",$R$3="Medium Effect",$U$3="Medium Effect"),$AU11,IF(AND($P$3="No",$R$3="No Effect",$U$3="Medium Effect"),$AS11,IF(AND($P$3="No",$R$3="No Effect",$U$3="Full Effect"),$AT11,IF(AND($P$3="No",$R$3="Medium Effect",$U$3="No Effect"),$AQ11,IF(AND($P$3="No",$R$3="Full Effect",$U$3="No Effect"),$AR11,IF(AND($P6="Yes",$R$3="No Effect",$U$3="No Effect"),$AY11,"Use FPTS per GP"))))))))))))))))) -> 4.585359 | AL11: =IFERROR(VLOOKUP(C11,CALC!$K$2:$M$8,2,FALSE),1) -> 0.96 | AM11: =IFERROR(VLOOKUP(C11,CALC!$K$2:$M$8,3,FALSE),1) -> 0.98 | AN11: =VLOOKUP(B11,CALC!$E$2:$H$33,3,FALSE) -> 1.09 | AO11: =VLOOKUP(B11,CALC!$E$2:$H$33,4,FALSE) -> 1.045 | AQ11: =$AA11*AM11 -> 10.029378 | AR11: =$AA11*AL11 -> 9.8246971 | AS11: =$AA11*AO11 -> 10.694592 | AT11: =$AA11*AN11 -> 11.155125 | AU11: =$AA11*AM11*AO11 -> 10.4807 | AV11: =$AA11*AM11*AN11 -> 10.932022 | AW11: =$AA11*AL11*AO11 -> 10.266809 | AX11: =$AA11*AL11*AN11 -> 10.70892 | AY11: =IF($C11="D",$AA11-$AE$3,$AA11-$AD$3) -> 4.4774524 | AZ11: =$AY11*AM11 -> 4.3879033 | BA11: =$AY11*AL11 -> 4.2983543 | BB11: =$AY11*AO11 -> 4.6789377 | BC11: =$AY11*AN11 -> 4.8804231 | BD11: =$AY11*AM11*AO11 -> 4.585359 | BE11: =$AY11*AM11*AN11 -> 4.7828146 | BF11: =$AY11*AL11*AO11 -> 4.4917802 | BG11: =$AY11*AL11*AN11 -> 4.6852062
A12: Auston Matthews | B12: TOR | C12: =VLOOKUP(A12,CALC!$A$2:$C$494,3,FALSE) -> C | D12: 1 | E12: 84 | F12: 51 | G12: 45.8 | H12: 96.8 | I12: 26.2 | J12: 344.8 | K12: 60.4 | L12: 100.5 | M12: 26 | N12: 0.148 | O12: 20.75 | P12: =IF(F$4="Yes",F12*F$5,0) -> 255 | Q12: =IF(G$4="Yes",G12*G$5,0) -> 171.75 | R12: =IF(H$4="Yes",H12*H$5,0) -> 96.8 | S12: =IF(I$4="Yes",I12*I$5,0) -> 13.1 | T12: =IF(J$4="Yes",J12*J$5,0) -> 172.4 | U12: =IF(K$4="Yes",K12*K$5,0) -> 18.12 | V12: =IF(L$4="Yes",L12*L$5,0) -> 60.3 | W12: =IF(M$4="Yes",M12*M$5,0) -> 26 | ... Y12: =IF(O$4="Yes",O12*O$5,0) -> 0 | Z12: =SUM(P12:Y12) -> 813.618 | AA12: =Z12/E12 -> 9.6859286 | AB12: =IF(AND($P$3="Yes",$R$3="Full Effect",$U$3="Full Effect"),$BG12,IF(AND($P$3="Yes",$R$3="Medium Effect",$U$3="Full Effect"),$BE12,IF(AND($P$3="Yes",$R$3="Full Effect",$U$3="Medium Effect"),$BF12,IF(AND($P$3="Yes",$R$3="Medium Effect",$U$3="Medium Effect"),$BD12,IF(AND($P$3="Yes",$R$3="No Effect",$U$3="Medium Effect"),$BB12,IF(AND($P$3="Yes",$R$3="No Effect",$U$3="Full Effect"),$BC12,IF(AND($P$3="Yes",$R$3="Medium Effect",$U$3="No Effect"),$AZ12,IF(AND($P$3="Yes",$R$3="Full Effect",$U$3="No Effect"),$BA12,IF(AND($P$3="No",$R$3="Full Effect",$U$3="Full Effect"),$AX12,IF(AND($P$3="No",$R$3="Medium Effect",$U$3="Full Effect"),$AV12,IF(AND($P$3="No",$R$3="Full Effect",$U$3="Medium Effect"),$AW12,IF(AND($P$3="No",$R$3="Medium Effect",$U$3="Medium Effect"),$AU12,IF(AND($P$3="No",$R$3="No Effect",$U$3="Medium Effect"),$AS12,IF(AND($P$3="No",$R$3="No Effect",$U$3="Full Effect"),$AT12,IF(AND($P$3="No",$R$3="Medium Effect",$U$3="No Effect"),$AQ12,IF(AND($P$3="No",$R$3="Full Effect",$U$3="No Effect"),$AR12,IF(AND($P7="Yes",$R$3="No Effect",$U$3="No Effect"),$AY12,"Use FPTS per GP"))))))))))))))))) -> 3.792974 | AL12: =IFERROR(VLOOKUP(C12,CALC!$K$2:$M$8,2,FALSE),1) -> 0.96 | AM12: =IFERROR(VLOOKUP(C12,CALC!$K$2:$M$8,3,FALSE),1) -> 0.98 | AN12: =VLOOKUP(B12,CALC!$E$2:$H$33,3,FALSE) -> 0.97 | AO12: =VLOOKUP(B12,CALC!$E$2:$H$33,4,FALSE) -> 0.985 | AQ12: =$AA12*AM12 -> 9.49221 | AR12: =$AA12*AL12 -> 9.2984914 | AS12: =$AA12*AO12 -> 9.5406396 | AT12: =$AA12*AN12 -> 9.3953507 | AU12: =$AA12*AM12*AO12 -> 9.3498268 | AV12: =$AA12*AM12*AN12 -> 9.2074437 | AW12: =$AA12*AL12*AO12 -> 9.1590141 | AX12: =$AA12*AL12*AN12 -> 9.0195367 | AY12: =IF($C12="D",$AA12-$AE$3,$AA12-$AD$3) -> 3.9293214 | AZ12: =$AY12*AM12 -> 3.850735 | BA12: =$AY12*AL12 -> 3.7721486 | BB12: =$AY12*AO12 -> 3.8703816 | BC12: =$AY12*AN12 -> 3.8114418 | BD12: =$AY12*AM12*AO12 -> 3.792974 | BE12: =$AY12*AM12*AN12 -> 3.735213 | BF12: =$AY12*AL12*AO12 -> 3.7155663 | BG12: =$AY12*AL12*AN12 -> 3.6589841
A13: David Pastrnak | B13: BOS | C13: =VLOOKUP(A13,CALC!$A$2:$C$494,3,FALSE) -> RW | D13: 1 | E13: 84 | F13: 39.2 | G13: 68 | H13: 107.1 | I13: 35.4 | J13: 313.3 | K13: 78.4 | L13: 29.3 | M13: 66.2 | N13: 0.125 | O13: 20.5 | P13: =IF(F$4="Yes",F13*F$5,0) -> 196 | Q13: =IF(G$4="Yes",G13*G$5,0) -> 255 | R13: =IF(H$4="Yes",H13*H$5,0) -> 107.1 | S13: =IF(I$4="Yes",I13*I$5,0) -> 17.7 | T13: =IF(J$4="Yes",J13*J$5,0) -> 156.65 | U13: =IF(K$4="Yes",K13*K$5,0) -> 23.52 | V13: =IF(L$4="Yes",L13*L$5,0) -> 17.58 | W13: =IF(M$4="Yes",M13*M$5,0) -> 66.2 | ... Y13: =IF(O$4="Yes",O13*O$5,0) -> 0 | Z13: =SUM(P13:Y13) -> 839.875 | AA13: =Z13/E13 -> 9.9985119 | AB13: =IF(AND($P$3="Yes",$R$3="Full Effect",$U$3="Full Effect"),$BG13,IF(AND($P$3="Yes",$R$3="Medium Effect",$U$3="Full Effect"),$BE13,IF(AND($P$3="Yes",$R$3="Full Effect",$U$3="Medium Effect"),$BF13,IF(AND($P$3="Yes",$R$3="Medium Effect",$U$3="Medium Effect"),$BD13,IF(AND($P$3="Yes",$R$3="No Effect",$U$3="Medium Effect"),$BB13,IF(AND($P$3="Yes",$R$3="No Effect",$U$3="Full Effect"),$BC13,IF(AND($P$3="Yes",$R$3="Medium Effect",$U$3="No Effect"),$AZ13,IF(AND($P$3="Yes",$R$3="Full Effect",$U$3="No Effect"),$BA13,IF(AND($P$3="No",$R$3="Full Effect",$U$3="Full Effect"),$AX13,IF(AND($P$3="No",$R$3="Medium Effect",$U$3="Full Effect"),$AV13,IF(AND($P$3="No",$R$3="Full Effect",$U$3="Medium Effect"),$AW13,IF(AND($P$3="No",$R$3="Medium Effect",$U$3="Medium Effect"),$AU13,IF(AND($P$3="No",$R$3="No Effect",$U$3="Medium Effect"),$AS13,IF(AND($P$3="No",$R$3="No Effect",$U$3="Full Effect"),$AT13,IF(AND($P$3="No",$R$3="Medium Effect",$U$3="No Effect"),$AQ13,IF(AND($P$3="No",$R$3="Full Effect",$U$3="No Effect"),$AR13,IF(AND($P8="Yes",$R$3="No Effect",$U$3="No Effect"),$AY13,"Use FPTS per GP"))))))))))))))))) -> 3.9911021 | AL13: =IFERROR(VLOOKUP(C13,CALC!$K$2:$M$8,2,FALSE),1) -> 0.95 | AM13: =IFERROR(VLOOKUP(C13,CALC!$K$2:$M$8,3,FALSE),1) -> 0.975 | AN13: =VLOOKUP(B13,CALC!$E$2:$H$33,3,FALSE) -> 0.93 | AO13: =VLOOKUP(B13,CALC!$E$2:$H$33,4,FALSE) -> 0.965 | AQ13: =$AA13*AM13 -> 9.7485491 | AR13: =$AA13*AL13 -> 9.4985863 | AS13: =$AA13*AO13 -> 9.648564 | AT13: =$AA13*AN13 -> 9.2986161 | AU13: =$AA13*AM13*AO13 -> 9.4073499 | AV13: =$AA13*AM13*AN13 -> 9.0661507 | AW13: =$AA13*AL13*AO13 -> 9.1661358 | AX13: =$AA13*AL13*AN13 -> 8.8336853 | AY13: =IF($C13="D",$AA13-$AE$3,$AA13-$AD$3) -> 4.2419048 | AZ13: =$AY13*AM13 -> 4.1358571 | BA13: =$AY13*AL13 -> 4.0298095 | BB13: =$AY13*AO13 -> 4.0934381 | BC13: =$AY13*AN13 -> 3.9449714 | BD13: =$AY13*AM13*AO13 -> 3.9911021 | BE13: =$AY13*AM13*AN13 -> 3.8463471 | BF13: =$AY13*AL13*AO13 -> 3.8887662 | BG13: =$AY13*AL13*AN13 -> 3.7477229
A14: Leon Draisaitl | B14: EDM | C14: =VLOOKUP(A14,CALC!$A$2:$C$494,3,FALSE) -> C/LW | D14: 1 | E14: 84 | F14: 42.9 | G14: 73.3 | H14: 116.2 | I14: 47.5 | J14: 227.9 | K14: 38 | L14: 30.6 | M14: 36.8 | N14: 0.188 | O14: 21 | P14: =IF(F$4="Yes",F14*F$5,0) -> 214.5 | Q14: =IF(G$4="Yes",G14*G$5,0) -> 274.875 | R14: =IF(H$4="Yes",H14*H$5,0) -> 116.2 | S14: =IF(I$4="Yes",I14*I$5,0) -> 23.75 | T14: =IF(J$4="Yes",J14*J$5,0) -> 113.95 | U14: =IF(K$4="Yes",K14*K$5,0) -> 11.4 | V14: =IF(L$4="Yes",L14*L$5,0) -> 18.36 | W14: =IF(M$4="Yes",M14*M$5,0) -> 36.8 | ... Y14: =IF(O$4="Yes",O14*O$5,0) -> 0 | Z14: =SUM(P14:Y14) -> 810.023 | AA14: =Z14/E14 -> 9.643131 | AB14: =IF(AND($P$3="Yes",$R$3="Full Effect",$U$3="Full Effect"),$BG14,IF(AND($P$3="Yes",$R$3="Medium Effect",$U$3="Full Effect"),$BE14,IF(AND($P$3="Yes",$R$3="Full Effect",$U$3="Medium Effect"),$BF14,IF(AND($P$3="Yes",$R$3="Medium Effect",$U$3="Medium Effect"),$BD14,IF(AND($P$3="Yes",$R$3="No Effect",$U$3="Medium Effect"),$BB14,IF(AND($P$3="Yes",$R$3="No Effect",$U$3="Full Effect"),$BC14,IF(AND($P$3="Yes",$R$3="Medium Effect",$U$3="No Effect"),$AZ14,IF(AND($P$3="Yes",$R$3="Full Effect",$U$3="No Effect"),$BA14,IF(AND($P$3="No",$R$3="Full Effect",$U$3="Full Effect"),$AX14,IF(AND($P$3="No",$R$3="Medium Effect",$U$3="Full Effect"),$AV14,IF(AND($P$3="No",$R$3="Full Effect",$U$3="Medium Effect"),$AW14,IF(AND($P$3="No",$R$3="Medium Effect",$U$3="Medium Effect"),$AU14,IF(AND($P$3="No",$R$3="No Effect",$U$3="Medium Effect"),$AS14,IF(AND($P$3="No",$R$3="No Effect",$U$3="Full Effect"),$AT14,IF(AND($P$3="No",$R$3="Medium Effect",$U$3="No Effect"),$AQ14,IF(AND($P$3="No",$R$3="Full Effect",$U$3="No Effect"),$AR14,IF(AND($P9="Yes",$R$3="No Effect",$U$3="No Effect"),$AY14,"Use FPTS per GP"))))))))))))))))) -> 4.2441812 | AL14: =IFERROR(VLOOKUP(C14,CALC!$K$2:$M$8,2,FALSE),1) -> 1.09 | AM14: =IFERROR(VLOOKUP(C14,CALC!$K$2:$M$8,3,FALSE),1) -> 1.045 | AN14: =VLOOKUP(B14,CALC!$E$2:$H$33,3,FALSE) -> 1.09 | AO14: =VLOOKUP(B14,CALC!$E$2:$H$33,4,FALSE) -> 1.045 | AQ14: =$AA14*AM14 -> 10.077072 | AR14: =$AA14*AL14 -> 10.511013 | AS14: =$AA14*AO14 -> 10.077072 | AT14: =$AA14*AN14 -> 10.511013 | AU14: =$AA14*AM14*AO14 -> 10.53054 | AV14: =$AA14*AM14*AN14 -> 10.984008 | AW14: =$AA14*AL14*AO14 -> 10.984008 | AX14: =$AA14*AL14*AN14 -> 11.457004 | AY14: =IF($C14="D",$AA14-$AE$3,$AA14-$AD$3) -> 3.8865238 | AZ14: =$AY14*AM14 -> 4.0614174 | BA14: =$AY14*AL14 -> 4.236311 | BB14: =$AY14*AO14 -> 4.0614174 | BC14: =$AY14*AN14 -> 4.236311 | BD14: =$AY14*AM14*AO14 -> 4.2441812 | BE14: =$AY14*AM14*AN14 -> 4.4269449 | BF14: =$AY14*AL14*AO14 -> 4.4269449 | BG14: =$AY14*AL14*AN14 -> 4.6175789
A15: Jack Eichel | B15: VGK | C15: =VLOOKUP(A15,CALC!$A$2:$C$494,3,FALSE) -> C | D15: 1 | E15: 84 | F15: 36.8 | G15: 65 | H15: 101.8 | I15: 32.4 | J15: 307.9 | K15: 39.9 | L15: 51.8 | M15: 19.5 | N15: 0.119 | O15: 21.25 | P15: =IF(F$4="Yes",F15*F$5,0) -> 184 | Q15: =IF(G$4="Yes",G15*G$5,0) -> 243.75 | R15: =IF(H$4="Yes",H15*H$5,0) -> 101.8 | S15: =IF(I$4="Yes",I15*I$5,0) -> 16.2 | T15: =IF(J$4="Yes",J15*J$5,0) -> 153.95 | U15: =IF(K$4="Yes",K15*K$5,0) -> 11.97 | V15: =IF(L$4="Yes",L15*L$5,0) -> 31.08 | W15: =IF(M$4="Yes",M15*M$5,0) -> 19.5 | ... Y15: =IF(O$4="Yes",O15*O$5,0) -> 0 | Z15: =SUM(P15:Y15) -> 762.369 | AA15: =Z15/E15 -> 9.0758214 | AB15: =IF(AND($P$3="Yes",$R$3="Full Effect",$U$3="Full Effect"),$BG15,IF(AND($P$3="Yes",$R$3="Medium Effect",$U$3="Full Effect"),$BE15,IF(AND($P$3="Yes",$R$3="Full Effect",$U$3="Medium Effect"),$BF15,IF(AND($P$3="Yes",$R$3="Medium Effect",$U$3="Medium Effect"),$BD15,IF(AND($P$3="Yes",$R$3="No Effect",$U$3="Medium Effect"),$BB15,IF(AND($P$3="Yes",$R$3="No Effect",$U$3="Full Effect"),$BC15,IF(AND($P$3="Yes",$R$3="Medium Effect",$U$3="No Effect"),$AZ15,IF(AND($P$3="Yes",$R$3="Full Effect",$U$3="No Effect"),$BA15,IF(AND($P$3="No",$R$3="Full Effect",$U$3="Full Effect"),$AX15,IF(AND($P$3="No",$R$3="Medium Effect",$U$3="Full Effect"),$AV15,IF(AND($P$3="No",$R$3="Full Effect",$U$3="Medium Effect"),$AW15,IF(AND($P$3="No",$R$3="Medium Effect",$U$3="Medium Effect"),$AU15,IF(AND($P$3="No",$R$3="No Effect",$U$3="Medium Effect"),$AS15,IF(AND($P$3="No",$R$3="No Effect",$U$3="Full Effect"),$AT15,IF(AND($P$3="No",$R$3="Medium Effect",$U$3="No Effect"),$AQ15,IF(AND($P$3="No",$R$3="Full Effect",$U$3="No Effect"),$AR15,IF(AND($P10="Yes",$R$3="No Effect",$U$3="No Effect"),$AY15,"Use FPTS per GP"))))))))))))))))) -> 3.25283 | AL15: =IFERROR(VLOOKUP(C15,CALC!$K$2:$M$8,2,FALSE),1) -> 0.96 | AM15: =IFERROR(VLOOKUP(C15,CALC!$K$2:$M$8,3,FALSE),1) -> 0.98 | AN15: =VLOOKUP(B15,CALC!$E$2:$H$33,3,FALSE) -> 1 | AO15: =VLOOKUP(B15,CALC!$E$2:$H$33,4,FALSE) -> 1 | AQ15: =$AA15*AM15 -> 8.894305 | AR15: =$AA15*AL15 -> 8.7127886 | AS15: =$AA15*AO15 -> 9.0758214 | AT15: =$AA15*AN15 -> 9.0758214 | AU15: =$AA15*AM15*AO15 -> 8.894305 | AV15: =$AA15*AM15*AN15 -> 8.894305 | AW15: =$AA15*AL15*AO15 -> 8.7127886 | AX15: =$AA15*AL15*AN15 -> 8.7127886 | AY15: =IF($C15="D",$AA15-$AE$3,$AA15-$AD$3) -> 3.3192143 | AZ15: =$AY15*AM15 -> 3.25283 | BA15: =$AY15*AL15 -> 3.1864457 | BB15: =$AY15*AO15 -> 3.3192143 | BC15: =$AY15*AN15 -> 3.3192143 | BD15: =$AY15*AM15*AO15 -> 3.25283 | BE15: =$AY15*AM15*AN15 -> 3.25283 | BF15: =$AY15*AL15*AO15 -> 3.1864457 | BG15: =$AY15*AL15*AN15 -> 3.1864457
A16: Jack Hughes | B16: NJD | C16: =VLOOKUP(A16,CALC!$A$2:$C$494,3,FALSE) -> C/LW | D16: 1 | E16: 84 | F16: 40.2 | G16: 62.3 | H16: 102.5 | I16: 33.9 | J16: 312.6 | K16: 7.6 | L16: 42.7 | M16: 16.7 | N16: 0.129 | O16: 21.25 | P16: =IF(F$4="Yes",F16*F$5,0) -> 201 | Q16: =IF(G$4="Yes",G16*G$5,0) -> 233.625 | R16: =IF(H$4="Yes",H16*H$5,0) -> 102.5 | S16: =IF(I$4="Yes",I16*I$5,0) -> 16.95 | T16: =IF(J$4="Yes",J16*J$5,0) -> 156.3 | U16: =IF(K$4="Yes",K16*K$5,0) -> 2.28 | V16: =IF(L$4="Yes",L16*L$5,0) -> 25.62 | W16: =IF(M$4="Yes",M16*M$5,0) -> 16.7 | ... Y16: =IF(O$4="Yes",O16*O$5,0) -> 0 | Z16: =SUM(P16:Y16) -> 755.104 | AA16: =Z16/E16 -> 8.9893333 | AB16: =IF(AND($P$3="Yes",$R$3="Full Effect",$U$3="Full Effect"),$BG16,IF(AND($P$3="Yes",$R$3="Medium Effect",$U$3="Full Effect"),$BE16,IF(AND($P$3="Yes",$R$3="Full Effect",$U$3="Medium Effect"),$BF16,IF(AND($P$3="Yes",$R$3="Medium Effect",$U$3="Medium Effect"),$BD16,IF(AND($P$3="Yes",$R$3="No Effect",$U$3="Medium Effect"),$BB16,IF(AND($P$3="Yes",$R$3="No Effect",$U$3="Full Effect"),$BC16,IF(AND($P$3="Yes",$R$3="Medium Effect",$U$3="No Effect"),$AZ16,IF(AND($P$3="Yes",$R$3="Full Effect",$U$3="No Effect"),$BA16,IF(AND($P$3="No",$R$3="Full Effect",$U$3="Full Effect"),$AX16,IF(AND($P$3="No",$R$3="Medium Effect",$U$3="Full Effect"),$AV16,IF(AND($P$3="No",$R$3="Full Effect",$U$3="Medium Effect"),$AW16,IF(AND($P$3="No",$R$3="Medium Effect",$U$3="Medium Effect"),$AU16,IF(AND($P$3="No",$R$3="No Effect",$U$3="Medium Effect"),$AS16,IF(AND($P$3="No",$R$3="No Effect",$U$3="Full Effect"),$AT16,IF(AND($P$3="No",$R$3="Medium Effect",$U$3="No Effect"),$AQ16,IF(AND($P$3="No",$R$3="Full Effect",$U$3="No Effect"),$AR16,IF(AND($P11="Yes",$R$3="No Effect",$U$3="No Effect"),$AY16,"Use FPTS per GP"))))))))))))))))) -> 3.2599619 | AL16: =IFERROR(VLOOKUP(C16,CALC!$K$2:$M$8,2,FALSE),1) -> 1.09 | AM16: =IFERROR(VLOOKUP(C16,CALC!$K$2:$M$8,3,FALSE),1) -> 1.045 | AN16: =VLOOKUP(B16,CALC!$E$2:$H$33,3,FALSE) -> 0.93 | AO16: =VLOOKUP(B16,CALC!$E$2:$H$33,4,FALSE) -> 0.965 | AQ16: =$AA16*AM16 -> 9.3938533 | AR16: =$AA16*AL16 -> 9.7983733 | AS16: =$AA16*AO16 -> 8.6747067 | AT16: =$AA16*AN16 -> 8.36008 | AU16: =$AA16*AM16*AO16 -> 9.0650685 | AV16: =$AA16*AM16*AN16 -> 8.7362836 | AW16: =$AA16*AL16*AO16 -> 9.4554303 | AX16: =$AA16*AL16*AN16 -> 9.1124872 | AY16: =IF($C16="D",$AA16-$AE$3,$AA16-$AD$3) -> 3.2327262 | AZ16: =$AY16*AM16 -> 3.3781989 | BA16: =$AY16*AL16 -> 3.5236715 | BB16: =$AY16*AO16 -> 3.1195808 | BC16: =$AY16*AN16 -> 3.0064354 | BD16: =$AY16*AM16*AO16 -> 3.2599619 | BE16: =$AY16*AM16*AN16 -> 3.1417249 | BF16: =$AY16*AL16*AO16 -> 3.400343 | BG16: =$AY16*AL16*AN16 -> 3.2770145
A17: Jason Robertson | B17: DAL | C17: =VLOOKUP(A17,CALC!$A$2:$C$494,3,FALSE) -> LW/RW | D17: 1 | E17: 84 | F17: 44.8 | G17: 53.5 | H17: 98.3 | I17: 39.4 | J17: 294.5 | K17: 54 | L17: 34.1 | M17: 28.4 | N17: 0.152 | O17: 20.25 | P17: =IF(F$4="Yes",F17*F$5,0) -> 224 | Q17: =IF(G$4="Yes",G17*G$5,0) -> 200.625 | R17: =IF(H$4="Yes",H17*H$5,0) -> 98.3 | S17: =IF(I$4="Yes",I17*I$5,0) -> 19.7 | T17: =IF(J$4="Yes",J17*J$5,0) -> 147.25 | U17: =IF(K$4="Yes",K17*K$5,0) -> 16.2 | V17: =IF(L$4="Yes",L17*L$5,0) -> 20.46 | W17: =IF(M$4="Yes",M17*M$5,0) -> 28.4 | ... Y17: =IF(O$4="Yes",O17*O$5,0) -> 0 | Z17: =SUM(P17:Y17) -> 755.087 | AA17: =Z17/E17 -> 8.989131 | AB17: =IF(AND($P$3="Yes",$R$3="Full Effect",$U$3="Full Effect"),$BG17,IF(AND($P$3="Yes",$R$3="Medium Effect",$U$3="Full Effect"),$BE17,IF(AND($P$3="Yes",$R$3="Full Effect",$U$3="Medium Effect"),$BF17,IF(AND($P$3="Yes",$R$3="Medium Effect",$U$3="Medium Effect"),$BD17,IF(AND($P$3="Yes",$R$3="No Effect",$U$3="Medium Effect"),$BB17,IF(AND($P$3="Yes",$R$3="No Effect",$U$3="Full Effect"),$BC17,IF(AND($P$3="Yes",$R$3="Medium Effect",$U$3="No Effect"),$AZ17,IF(AND($P$3="Yes",$R$3="Full Effect",$U$3="No Effect"),$BA17,IF(AND($P$3="No",$R$3="Full Effect",$U$3="Full Effect"),$AX17,IF(AND($P$3="No",$R$3="Medium Effect",$U$3="Full Effect"),$AV17,IF(AND($P$3="No",$R$3="Full Effect",$U$3="Medium Effect"),$AW17,IF(AND($P$3="No",$R$3="Medium Effect",$U$3="Medium Effect"),$AU17,IF(AND($P$3="No",$R$3="No Effect",$U$3="Medium Effect"),$AS17,IF(AND($P$3="No",$R$3="No Effect",$U$3="Full Effect"),$AT17,IF(AND($P$3="No",$R$3="Medium Effect",$U$3="No Effect"),$AQ17,IF(AND($P$3="No",$R$3="Full Effect",$U$3="No Effect"),$AR17,IF(AND($P12="Yes",$R$3="No Effect",$U$3="No Effect"),$AY17,"Use FPTS per GP"))))))))))))))))) -> 3.4290613 | AL17: =IFERROR(VLOOKUP(C17,CALC!$K$2:$M$8,2,FALSE),1) -> 1.08 | AM17: =IFERROR(VLOOKUP(C17,CALC!$K$2:$M$8,3,FALSE),1) -> 1.04 | AN17: =VLOOKUP(B17,CALC!$E$2:$H$33,3,FALSE) -> 1.04 | AO17: =VLOOKUP(B17,CALC!$E$2:$H$33,4,FALSE) -> 1.02 | AQ17: =$AA17*AM17 -> 9.3486962 | AR17: =$AA17*AL17 -> 9.7082614 | AS17: =$AA17*AO17 -> 9.1689136 | AT17: =$AA17*AN17 -> 9.3486962 | AU17: =$AA17*AM17*AO17 -> 9.5356701 | AV17: =$AA17*AM17*AN17 -> 9.722644 | AW17: =$AA17*AL17*AO17 -> 9.9024267 | AX17: =$AA17*AL17*AN17 -> 10.096592 | AY17: =IF($C17="D",$AA17-$AE$3,$AA17-$AD$3) -> 3.2325238 | AZ17: =$AY17*AM17 -> 3.3618248 | BA17: =$AY17*AL17 -> 3.4911257 | BB17: =$AY17*AO17 -> 3.2971743 | BC17: =$AY17*AN17 -> 3.3618248 | BD17: =$AY17*AM17*AO17 -> 3.4290613 | BE17: =$AY17*AM17*AN17 -> 3.4962978 | BF17: =$AY17*AL17*AO17 -> 3.5609482 | BG17: =$AY17*AL17*AN17 -> 3.6307707
A18: Kirill Kaprizov | B18: MIN | C18: =VLOOKUP(A18,CALC!$A$2:$C$494,3,FALSE) -> LW | D18: 1 | E18: 84 | F18: 46.2 | G18: 52.2 | H18: 98.4 | I18: 33.8 | J18: 278.3 | K18: 54.7 | L18: 32 | M18: 31.7 | N18: 0.166 | O18: 21.75 | P18: =IF(F$4="Yes",F18*F$5,0) -> 231 | Q18: =IF(G$4="Yes",G18*G$5,0) -> 195.75 | R18: =IF(H$4="Yes",H18*H$5,0) -> 98.4 | S18: =IF(I$4="Yes",I18*I$5,0) -> 16.9 | T18: =IF(J$4="Yes",J18*J$5,0) -> 139.15 | U18: =IF(K$4="Yes",K18*K$5,0) -> 16.41 | V18: =IF(L$4="Yes",L18*L$5,0) -> 19.2 | W18: =IF(M$4="Yes",M18*M$5,0) -> 31.7 | ... Y18: =IF(O$4="Yes",O18*O$5,0) -> 0 | Z18: =SUM(P18:Y18) -> 748.676 | AA18: =Z18/E18 -> 8.9128095 | AB18: =IF(AND($P$3="Yes",$R$3="Full Effect",$U$3="Full Effect"),$BG18,IF(AND($P$3="Yes",$R$3="Medium Effect",$U$3="Full Effect"),$BE18,IF(AND($P$3="Yes",$R$3="Full Effect",$U$3="Medium Effect"),$BF18,IF(AND($P$3="Yes",$R$3="Medium Effect",$U$3="Medium Effect"),$BD18,IF(AND($P$3="Yes",$R$3="No Effect",$U$3="Medium Effect"),$BB18,IF(AND($P$3="Yes",$R$3="No Effect",$U$3="Full Effect"),$BC18,IF(AND($P$3="Yes",$R$3="Medium Effect",$U$3="No Effect"),$AZ18,IF(AND($P$3="Yes",$R$3="Full Effect",$U$3="No Effect"),$BA18,IF(AND($P$3="No",$R$3="Full Effect",$U$3="Full Effect"),$AX18,IF(AND($P$3="No",$R$3="Medium Effect",$U$3="Full Effect"),$AV18,IF(AND($P$3="No",$R$3="Full Effect",$U$3="Medium Effect"),$AW18,IF(AND($P$3="No",$R$3="Medium Effect",$U$3="Medium Effect"),$AU18,IF(AND($P$3="No",$R$3="No Effect",$U$3="Medium Effect"),$AS18,IF(AND($P$3="No",$R$3="No Effect",$U$3="Full Effect"),$AT18,IF(AND($P$3="No",$R$3="Medium Effect",$U$3="No Effect"),$AQ18,IF(AND($P$3="No",$R$3="Full Effect",$U$3="No Effect"),$AR18,IF(AND($P13="Yes",$R$3="No Effect",$U$3="No Effect"),$AY18,"Use FPTS per GP"))))))))))))))))) -> 3.088344 | AL18: =IFERROR(VLOOKUP(C18,CALC!$K$2:$M$8,2,FALSE),1) -> 1.06 | AM18: =IFERROR(VLOOKUP(C18,CALC!$K$2:$M$8,3,FALSE),1) -> 1.03 | AN18: =VLOOKUP(B18,CALC!$E$2:$H$33,3,FALSE) -> 0.9 | AO18: =VLOOKUP(B18,CALC!$E$2:$H$33,4,FALSE) -> 0.95 | AQ18: =$AA18*AM18 -> 9.1801938 | AR18: =$AA18*AL18 -> 9.4475781 | AS18: =$AA18*AO18 -> 8.467169 | AT18: =$AA18*AN18 -> 8.0215286 | AU18: =$AA18*AM18*AO18 -> 8.7211841 | AV18: =$AA18*AM18*AN18 -> 8.2621744 | AW18: =$AA18*AL18*AO18 -> 8.9751992 | AX18: =$AA18*AL18*AN18 -> 8.5028203 | AY18: =IF($C18="D",$AA18-$AE$3,$AA18-$AD$3) -> 3.1562024 | AZ18: =$AY18*AM18 -> 3.2508885 | BA18: =$AY18*AL18 -> 3.3455745 | BB18: =$AY18*AO18 -> 2.9983923 | BC18: =$AY18*AN18 -> 2.8405821 | BD18: =$AY18*AM18*AO18 -> 3.088344 | BE18: =$AY18*AM18*AN18 -> 2.9257996 | BF18: =$AY18*AL18*AO18 -> 3.1782958 | BG18: =$AY18*AL18*AN18 -> 3.0110171
A19: Cale Makar | B19: COL | C19: =VLOOKUP(A19,CALC!$A$2:$C$494,3,FALSE) -> D | D19: 1 | E19: 84 | F19: 25 | G19: 68.9 | H19: 93.9 | I19: 35.7 | J19: 237 | K19: 44.2 | L19: 131.6 | M19: 21.4 | N19: 0.106 | O19: 25 | P19: =IF(F$4="Yes",F19*F$5,0) -> 125 | Q19: =IF(G$4="Yes",G19*G$5,0) -> 258.375 | R19: =IF(H$4="Yes",H19*H$5,0) -> 93.9 | S19: =IF(I$4="Yes",I19*I$5,0) -> 17.85 | T19: =IF(J$4="Yes",J19*J$5,0) -> 118.5 | U19: =IF(K$4="Yes",K19*K$5,0) -> 13.26 | V19: =IF(L$4="Yes",L19*L$5,0) -> 78.96 | W19: =IF(M$4="Yes",M19*M$5,0) -> 21.4 | ... Y19: =IF(O$4="Yes",O19*O$5,0) -> 0 | Z19: =SUM(P19:Y19) -> 727.351 | AA19: =Z19/E19 -> 8.6589405 | AB19: =IF(AND($P$3="Yes",$R$3="Full Effect",$U$3="Full Effect"),$BG19,IF(AND($P$3="Yes",$R$3="Medium Effect",$U$3="Full Effect"),$BE19,IF(AND($P$3="Yes",$R$3="Full Effect",$U$3="Medium Effect"),$BF19,IF(AND($P$3="Yes",$R$3="Medium Effect",$U$3="Medium Effect"),$BD19,IF(AND($P$3="Yes",$R$3="No Effect",$U$3="Medium Effect"),$BB19,IF(AND($P$3="Yes",$R$3="No Effect",$U$3="Full Effect"),$BC19,IF(AND($P$3="Yes",$R$3="Medium Effect",$U$3="No Effect"),$AZ19,IF(AND($P$3="Yes",$R$3="Full Effect",$U$3="No Effect"),$BA19,IF(AND($P$3="No",$R$3="Full Effect",$U$3="Full Effect"),$AX19,IF(AND($P$3="No",$R$3="Medium Effect",$U$3="Full Effect"),$AV19,IF(AND($P$3="No",$R$3="Full Effect",$U$3="Medium Effect"),$AW19,IF(AND($P$3="No",$R$3="Medium Effect",$U$3="Medium Effect"),$AU19,IF(AND($P$3="No",$R$3="No Effect",$U$3="Medium Effect"),$AS19,IF(AND($P$3="No",$R$3="No Effect",$U$3="Full Effect"),$AT19,IF(AND($P$3="No",$R$3="Medium Effect",$U$3="No Effect"),$AQ19,IF(AND($P$3="No",$R$3="Full Effect",$U$3="No Effect"),$AR19,IF(AND($P14="Yes",$R$3="No Effect",$U$3="No Effect"),$AY19,"Use FPTS per GP"))))))))))))))))) -> 4.0064239 | AL19: =IFERROR(VLOOKUP(C19,CALC!$K$2:$M$8,2,FALSE),1) -> 1 | AM19: =IFERROR(VLOOKUP(C19,CALC!$K$2:$M$8,3,FALSE),1) -> 1 | AN19: =VLOOKUP(B19,CALC!$E$2:$H$33,3,FALSE) -> 1.14 | AO19: =VLOOKUP(B19,CALC!$E$2:$H$33,4,FALSE) -> 1.07 | AQ19: =$AA19*AM19 -> 8.6589405 | AR19: =$AA19*AL19 -> 8.6589405 | AS19: =$AA19*AO19 -> 9.2650663 | AT19: =$AA19*AN19 -> 9.8711921 | AU19: =$AA19*AM19*AO19 -> 9.2650663 | AV19: =$AA19*AM19*AN19 -> 9.8711921 | AW19: =$AA19*AL19*AO19 -> 9.2650663 | AX19: =$AA19*AL19*AN19 -> 9.8711921 | AY19: =IF($C19="D",$AA19-$AE$3,$AA19-$AD$3) -> 3.7443214 | AZ19: =$AY19*AM19 -> 3.7443214 | BA19: =$AY19*AL19 -> 3.7443214 | BB19: =$AY19*AO19 -> 4.0064239 | BC19: =$AY19*AN19 -> 4.2685264 | BD19: =$AY19*AM19*AO19 -> 4.0064239 | BE19: =$AY19*AM19*AN19 -> 4.2685264 | BF19: =$AY19*AL19*AO19 -> 4.0064239 | BG19: =$AY19*AL19*AN19 -> 4.2685264
... A170: Thomas Harley | B170: DAL | C170: =VLOOKUP(A170,CALC!$A$2:$C$494,3,FALSE) -> D | D170: 2 | E170: 84 | F170: 13.9 | G170: 32 | H170: 45.9 | I170: 9.4 | J170: 140.4 | K170: 41.2 | L170: 175.4 | M170: 24.5 | N170: 0.099 | O170: 23.25 | P170: =IF(F$4="Yes",F170*F$5,0) -> 69.5 | Q170: =IF(G$4="Yes",G170*G$5,0) -> 120 | R170: =IF(H$4="Yes",H170*H$5,0) -> 45.9 | S170: =IF(I$4="Yes",I170*I$5,0) -> 4.7 | T170: =IF(J$4="Yes",J170*J$5,0) -> 70.2 | U170: =IF(K$4="Yes",K170*K$5,0) -> 12.36 | V170: =IF(L$4="Yes",L170*L$5,0) -> 105.24 | W170: =IF(M$4="Yes",M170*M$5,0) -> 24.5 | ... Y170: =IF(O$4="Yes",O170*O$5,0) -> 0 | Z170: =SUM(P170:Y170) -> 452.499 | AA170: =Z170/E170 -> 5.3868929 | AB170: =IF(AND($P$3="Yes",$R$3="Full Effect",$U$3="Full Effect"),$BG170,IF(AND($P$3="Yes",$R$3="Medium Effect",$U$3="Full Effect"),$BE170,IF(AND($P$3="Yes",$R$3="Full Effect",$U$3="Medium Effect"),$BF170,IF(AND($P$3="Yes",$R$3="Medium Effect",$U$3="Medium Effect"),$BD170,IF(AND($P$3="Yes",$R$3="No Effect",$U$3="Medium Effect"),$BB170,IF(AND($P$3="Yes",$R$3="No Effect",$U$3="Full Effect"),$BC170,IF(AND($P$3="Yes",$R$3="Medium Effect",$U$3="No Effect"),$AZ170,IF(AND($P$3="Yes",$R$3="Full Effect",$U$3="No Effect"),$BA170,IF(AND($P$3="No",$R$3="Full Effect",$U$3="Full Effect"),$AX170,IF(AND($P$3="No",$R$3="Medium Effect",$U$3="Full Effect"),$AV170,IF(AND($P$3="No",$R$3="Full Effect",$U$3="Medium Effect"),$AW170,IF(AND($P$3="No",$R$3="Medium Effect",$U$3="Medium Effect"),$AU170,IF(AND($P$3="No",$R$3="No Effect",$U$3="Medium Effect"),$AS170,IF(AND($P$3="No",$R$3="No Effect",$U$3="Full Effect"),$AT170,IF(AND($P$3="No",$R$3="Medium Effect",$U$3="No Effect"),$AQ170,IF(AND($P$3="No",$R$3="Full Effect",$U$3="No Effect"),$AR170,IF(AND($P165="Yes",$R$3="No Effect",$U$3="No Effect"),$AY170,"Use FPTS per GP"))))))))))))))))) -> 0.48171929 | AL170: =IFERROR(VLOOKUP(C170,CALC!$K$2:$M$8,2,FALSE),1) -> 1 | AM170: =IFERROR(VLOOKUP(C170,CALC!$K$2:$M$8,3,FALSE),1) -> 1 | AN170: =VLOOKUP(B170,CALC!$E$2:$H$33,3,FALSE) -> 1.04 | AO170: =VLOOKUP(B170,CALC!$E$2:$H$33,4,FALSE) -> 1.02 | AQ170: =$AA170*AM170 -> 5.3868929 | AR170: =$AA170*AL170 -> 5.3868929 | AS170: =$AA170*AO170 -> 5.4946307 | AT170: =$AA170*AN170 -> 5.6023686 | AU170: =$AA170*AM170*AO170 -> 5.4946307 | AV170: =$AA170*AM170*AN170 -> 5.6023686 | AW170: =$AA170*AL170*AO170 -> 5.4946307 | AX170: =$AA170*AL170*AN170 -> 5.6023686 | AY170: =IF($C170="D",$AA170-$AE$3,$AA170-$AD$3) -> 0.47227381 | AZ170: =$AY170*AM170 -> 0.47227381 | BA170: =$AY170*AL170 -> 0.47227381 | BB170: =$AY170*AO170 -> 0.48171929 | BC170: =$AY170*AN170 -> 0.49116476 | BD170: =$AY170*AM170*AO170 -> 0.48171929 | BE170: =$AY170*AM170*AN170 -> 0.49116476 | BF170: =$AY170*AL170*AO170 -> 0.48171929 | BG170: =$AY170*AL170*AN170 -> 0.49116476
A171: Boone Jenner | B171: WSH | C171: =VLOOKUP(A171,CALC!$A$2:$C$494,3,FALSE) -> C/LW | E171: 84 | F171: 20.7 | G171: 24.4 | H171: 45 | I171: 6.4 | J171: 177.6 | K171: 169.4 | L171: 73.6 | M171: 46 | N171: 0.116 | O171: 16.75 | P171: =IF(F$4="Yes",F171*F$5,0) -> 103.5 | Q171: =IF(G$4="Yes",G171*G$5,0) -> 91.5 | R171: =IF(H$4="Yes",H171*H$5,0) -> 45 | S171: =IF(I$4="Yes",I171*I$5,0) -> 3.2 | T171: =IF(J$4="Yes",J171*J$5,0) -> 88.8 | U171: =IF(K$4="Yes",K171*K$5,0) -> 50.82 | V171: =IF(L$4="Yes",L171*L$5,0) -> 44.16 | W171: =IF(M$4="Yes",M171*M$5,0) -> 46 | ... Y171: =IF(O$4="Yes",O171*O$5,0) -> 0 | Z171: =SUM(P171:Y171) -> 473.096 | AA171: =Z171/E171 -> 5.6320952 | AB171: =IF(AND($P$3="Yes",$R$3="Full Effect",$U$3="Full Effect"),$BG171,IF(AND($P$3="Yes",$R$3="Medium Effect",$U$3="Full Effect"),$BE171,IF(AND($P$3="Yes",$R$3="Full Effect",$U$3="Medium Effect"),$BF171,IF(AND($P$3="Yes",$R$3="Medium Effect",$U$3="Medium Effect"),$BD171,IF(AND($P$3="Yes",$R$3="No Effect",$U$3="Medium Effect"),$BB171,IF(AND($P$3="Yes",$R$3="No Effect",$U$3="Full Effect"),$BC171,IF(AND($P$3="Yes",$R$3="Medium Effect",$U$3="No Effect"),$AZ171,IF(AND($P$3="Yes",$R$3="Full Effect",$U$3="No Effect"),$BA171,IF(AND($P$3="No",$R$3="Full Effect",$U$3="Full Effect"),$AX171,IF(AND($P$3="No",$R$3="Medium Effect",$U$3="Full Effect"),$AV171,IF(AND($P$3="No",$R$3="Full Effect",$U$3="Medium Effect"),$AW171,IF(AND($P$3="No",$R$3="Medium Effect",$U$3="Medium Effect"),$AU171,IF(AND($P$3="No",$R$3="No Effect",$U$3="Medium Effect"),$AS171,IF(AND($P$3="No",$R$3="No Effect",$U$3="Full Effect"),$AT171,IF(AND($P$3="No",$R$3="Medium Effect",$U$3="No Effect"),$AQ171,IF(AND($P$3="No",$R$3="Full Effect",$U$3="No Effect"),$AR171,IF(AND($P166="Yes",$R$3="No Effect",$U$3="No Effect"),$AY171,"Use FPTS per GP"))))))))))))))))) -> -0.14247586 | AL171: =IFERROR(VLOOKUP(C171,CALC!$K$2:$M$8,2,FALSE),1) -> 1.09 | AM171: =IFERROR(VLOOKUP(C171,CALC!$K$2:$M$8,3,FALSE),1) -> 1.045 | AN171: =VLOOKUP(B171,CALC!$E$2:$H$33,3,FALSE) -> 1.19 | AO171: =VLOOKUP(B171,CALC!$E$2:$H$33,4,FALSE) -> 1.095 | AQ171: =$AA171*AM171 -> 5.8855395 | AR171: =$AA171*AL171 -> 6.1389838 | AS171: =$AA171*AO171 -> 6.1671443 | AT171: =$AA171*AN171 -> 6.7021933 | AU171: =$AA171*AM171*AO171 -> 6.4446658 | AV171: =$AA171*AM171*AN171 -> 7.003792 | AW171: =$AA171*AL171*AO171 -> 6.7221873 | AX171: =$AA171*AL171*AN171 -> 7.3053907 | AY171: =IF($C171="D",$AA171-$AE$3,$AA171-$AD$3) -> -0.1245119 | AZ171: =$AY171*AM171 -> -0.13011494 | BA171: =$AY171*AL171 -> -0.13571798 | BB171: =$AY171*AO171 -> -0.13634054 | BC171: =$AY171*AN171 -> -0.14816917 | BD171: =$AY171*AM171*AO171 -> -0.14247586 | BE171: =$AY171*AM171*AN171 -> -0.15483678 | BF171: =$AY171*AL171*AO171 -> -0.14861118 | BG171: =$AY171*AL171*AN171 -> -0.16150439
A172: Jacob Trouba | B172: SJS | C172: =VLOOKUP(A172,CALC!$A$2:$C$494,3,FALSE) -> D | D172: 2 | E172: 84 | F172: 9.3 | G172: 24.7 | H172: 34 | I172: 3.2 | J172: 171.2 | K172: 154.7 | L172: 178.5 | M172: 55.3 | N172: 0.054 | O172: 23 | P172: =IF(F$4="Yes",F172*F$5,0) -> 46.5 | Q172: =IF(G$4="Yes",G172*G$5,0) -> 92.625 | R172: =IF(H$4="Yes",H172*H$5,0) -> 34 | S172: =IF(I$4="Yes",I172*I$5,0) -> 1.6 | T172: =IF(J$4="Yes",J172*J$5,0) -> 85.6 | U172: =IF(K$4="Yes",K172*K$5,0) -> 46.41 | V172: =IF(L$4="Yes",L172*L$5,0) -> 107.1 | W172: =IF(M$4="Yes",M172*M$5,0) -> 55.3 | ... Y172: =IF(O$4="Yes",O172*O$5,0) -> 0 | Z172: =SUM(P172:Y172) -> 469.189 | AA172: =Z172/E172 -> 5.5855833 | AB172: =IF(AND($P$3="Yes",$R$3="Full Effect",$U$3="Full Effect"),$BG172,IF(AND($P$3="Yes",$R$3="Medium Effect",$U$3="Full Effect"),$BE172,IF(AND($P$3="Yes",$R$3="Full Effect",$U$3="Medium Effect"),$BF172,IF(AND($P$3="Yes",$R$3="Medium Effect",$U$3="Medium Effect"),$BD172,IF(AND($P$3="Yes",$R$3="No Effect",$U$3="Medium Effect"),$BB172,IF(AND($P$3="Yes",$R$3="No Effect",$U$3="Full Effect"),$BC172,IF(AND($P$3="Yes",$R$3="Medium Effect",$U$3="No Effect"),$AZ172,IF(AND($P$3="Yes",$R$3="Full Effect",$U$3="No Effect"),$BA172,IF(AND($P$3="No",$R$3="Full Effect",$U$3="Full Effect"),$AX172,IF(AND($P$3="No",$R$3="Medium Effect",$U$3="Full Effect"),$AV172,IF(AND($P$3="No",$R$3="Full Effect",$U$3="Medium Effect"),$AW172,IF(AND($P$3="No",$R$3="Medium Effect",$U$3="Medium Effect"),$AU172,IF(AND($P$3="No",$R$3="No Effect",$U$3="Medium Effect"),$AS172,IF(AND($P$3="No",$R$3="No Effect",$U$3="Full Effect"),$AT172,IF(AND($P$3="No",$R$3="Medium Effect",$U$3="No Effect"),$AQ172,IF(AND($P$3="No",$R$3="Full Effect",$U$3="No Effect"),$AR172,IF(AND($P167="Yes",$R$3="No Effect",$U$3="No Effect"),$AY172,"Use FPTS per GP"))))))))))))))))) -> 0.70115768 | AL172: =IFERROR(VLOOKUP(C172,CALC!$K$2:$M$8,2,FALSE),1) -> 1 | AM172: =IFERROR(VLOOKUP(C172,CALC!$K$2:$M$8,3,FALSE),1) -> 1 | AN172: =VLOOKUP(B172,CALC!$E$2:$H$33,3,FALSE) -> 1.09 | AO172: =VLOOKUP(B172,CALC!$E$2:$H$33,4,FALSE) -> 1.045 | AQ172: =$AA172*AM172 -> 5.5855833 | AR172: =$AA172*AL172 -> 5.5855833 | AS172: =$AA172*AO172 -> 5.8369346 | AT172: =$AA172*AN172 -> 6.0882858 | AU172: =$AA172*AM172*AO172 -> 5.8369346 | AV172: =$AA172*AM172*AN172 -> 6.0882858 | AW172: =$AA172*AL172*AO172 -> 5.8369346 | AX172: =$AA172*AL172*AN172 -> 6.0882858 | AY172: =IF($C172="D",$AA172-$AE$3,$AA172-$AD$3) -> 0.67096429 | AZ172: =$AY172*AM172 -> 0.67096429 | BA172: =$AY172*AL172 -> 0.67096429 | BB172: =$AY172*AO172 -> 0.70115768 | BC172: =$AY172*AN172 -> 0.73135107 | BD172: =$AY172*AM172*AO172 -> 0.70115768 | BE172: =$AY172*AM172*AN172 -> 0.73135107 | BF172: =$AY172*AL172*AO172 -> 0.70115768 | BG172: =$AY172*AL172*AN172 -> 0.73135107
A173: Ryan Leonard | B173: WSH | C173: =VLOOKUP(A173,CALC!$A$2:$C$494,3,FALSE) -> RW | D173: 2 | E173: 84 | F173: 23.5 | G173: 27.8 | H173: 51.2 | I173: 12.3 | J173: 177.8 | K173: 144.2 | L173: 31.2 | M173: 53.3 | N173: 0.132 | O173: 14.75 | P173: =IF(F$4="Yes",F173*F$5,0) -> 117.5 | Q173: =IF(G$4="Yes",G173*G$5,0) -> 104.25 | R173: =IF(H$4="Yes",H173*H$5,0) -> 51.2 | S173: =IF(I$4="Yes",I173*I$5,0) -> 6.15 | T173: =IF(J$4="Yes",J173*J$5,0) -> 88.9 | U173: =IF(K$4="Yes",K173*K$5,0) -> 43.26 | V173: =IF(L$4="Yes",L173*L$5,0) -> 18.72 | W173: =IF(M$4="Yes",M173*M$5,0) -> 53.3 | ... Y173: =IF(O$4="Yes",O173*O$5,0) -> 0 | Z173: =SUM(P173:Y173) -> 483.412 | AA173: =Z173/E173 -> 5.7549048 | AB173: =IF(AND($P$3="Yes",$R$3="Full Effect",$U$3="Full Effect"),$BG173,IF(AND($P$3="Yes",$R$3="Medium Effect",$U$3="Full Effect"),$BE173,IF(AND($P$3="Yes",$R$3="Full Effect",$U$3="Medium Effect"),$BF173,IF(AND($P$3="Yes",$R$3="Medium Effect",$U$3="Medium Effect"),$BD173,IF(AND($P$3="Yes",$R$3="No Effect",$U$3="Medium Effect"),$BB173,IF(AND($P$3="Yes",$R$3="No Effect",$U$3="Full Effect"),$BC173,IF(AND($P$3="Yes",$R$3="Medium Effect",$U$3="No Effect"),$AZ173,IF(AND($P$3="Yes",$R$3="Full Effect",$U$3="No Effect"),$BA173,IF(AND($P$3="No",$R$3="Full Effect",$U$3="Full Effect"),$AX173,IF(AND($P$3="No",$R$3="Medium Effect",$U$3="Full Effect"),$AV173,IF(AND($P$3="No",$R$3="Full Effect",$U$3="Medium Effect"),$AW173,IF(AND($P$3="No",$R$3="Medium Effect",$U$3="Medium Effect"),$AU173,IF(AND($P$3="No",$R$3="No Effect",$U$3="Medium Effect"),$AS173,IF(AND($P$3="No",$R$3="No Effect",$U$3="Full Effect"),$AT173,IF(AND($P$3="No",$R$3="Medium Effect",$U$3="No Effect"),$AQ173,IF(AND($P$3="No",$R$3="Full Effect",$U$3="No Effect"),$AR173,IF(AND($P168="Yes",$R$3="No Effect",$U$3="No Effect"),$AY173,"Use FPTS per GP"))))))))))))))))) -> -0.0018175045 | AL173: =IFERROR(VLOOKUP(C173,CALC!$K$2:$M$8,2,FALSE),1) -> 0.95 | AM173: =IFERROR(VLOOKUP(C173,CALC!$K$2:$M$8,3,FALSE),1) -> 0.975 | AN173: =VLOOKUP(B173,CALC!$E$2:$H$33,3,FALSE) -> 1.19 | AO173: =VLOOKUP(B173,CALC!$E$2:$H$33,4,FALSE) -> 1.095 | AQ173: =$AA173*AM173 -> 5.6110321 | AR173: =$AA173*AL173 -> 5.4671595 | AS173: =$AA173*AO173 -> 6.3016207 | AT173: =$AA173*AN173 -> 6.8483367 | AU173: =$AA173*AM173*AO173 -> 6.1440802 | AV173: =$AA173*AM173*AN173 -> 6.6771282 | AW173: =$AA173*AL173*AO173 -> 5.9865397 | AX173: =$AA173*AL173*AN173 -> 6.5059198 | AY173: =IF($C173="D",$AA173-$AE$3,$AA173-$AD$3) -> -0.001702381 | AZ173: =$AY173*AM173 -> -0.0016598214 | BA173: =$AY173*AL173 -> -0.0016172619 | BB173: =$AY173*AO173 -> -0.0018641071 | BC173: =$AY173*AN173 -> -0.0020258333 | BD173: =$AY173*AM173*AO173 -> -0.0018175045 | BE173: =$AY173*AM173*AN173 -> -0.0019751875 | BF173: =$AY173*AL173*AO173 -> -0.0017709018 | BG173: =$AY173*AL173*AN173 -> -0.0019245417
A174: Brock Faber | B174: MIN | C174: =VLOOKUP(A174,CALC!$A$2:$C$494,3,FALSE) -> D | D174: 2 | E174: 84 | F174: 13.9 | G174: 32.1 | H174: 46 | I174: 6.9 | J174: 171 | K174: 32.5 | L174: 149.9 | M174: 34.1 | N174: 0.081 | O174: 24.25 | P174: =IF(F$4="Yes",F174*F$5,0) -> 69.5 | Q174: =IF(G$4="Yes",G174*G$5,0) -> 120.375 | R174: =IF(H$4="Yes",H174*H$5,0) -> 46 | S174: =IF(I$4="Yes",I174*I$5,0) -> 3.45 | T174: =IF(J$4="Yes",J174*J$5,0) -> 85.5 | U174: =IF(K$4="Yes",K174*K$5,0) -> 9.75 | V174: =IF(L$4="Yes",L174*L$5,0) -> 89.94 | W174: =IF(M$4="Yes",M174*M$5,0) -> 34.1 | ... Y174: =IF(O$4="Yes",O174*O$5,0) -> 0 | Z174: =SUM(P174:Y174) -> 458.696 | AA174: =Z174/E174 -> 5.4606667 | AB174: =IF(AND($P$3="Yes",$R$3="Full Effect",$U$3="Full Effect"),$BG174,IF(AND($P$3="Yes",$R$3="Medium Effect",$U$3="Full Effect"),$BE174,IF(AND($P$3="Yes",$R$3="Full Effect",$U$3="Medium Effect"),$BF174,IF(AND($P$3="Yes",$R$3="Medium Effect",$U$3="Medium Effect"),$BD174,IF(AND($P$3="Yes",$R$3="No Effect",$U$3="Medium Effect"),$BB174,IF(AND($P$3="Yes",$R$3="No Effect",$U$3="Full Effect"),$BC174,IF(AND($P$3="Yes",$R$3="Medium Effect",$U$3="No Effect"),$AZ174,IF(AND($P$3="Yes",$R$3="Full Effect",$U$3="No Effect"),$BA174,IF(AND($P$3="No",$R$3="Full Effect",$U$3="Full Effect"),$AX174,IF(AND($P$3="No",$R$3="Medium Effect",$U$3="Full Effect"),$AV174,IF(AND($P$3="No",$R$3="Full Effect",$U$3="Medium Effect"),$AW174,IF(AND($P$3="No",$R$3="Medium Effect",$U$3="Medium Effect"),$AU174,IF(AND($P$3="No",$R$3="No Effect",$U$3="Medium Effect"),$AS174,IF(AND($P$3="No",$R$3="No Effect",$U$3="Full Effect"),$AT174,IF(AND($P$3="No",$R$3="Medium Effect",$U$3="No Effect"),$AQ174,IF(AND($P$3="No",$R$3="Full Effect",$U$3="No Effect"),$AR174,IF(AND($P169="Yes",$R$3="No Effect",$U$3="No Effect"),$AY174,"Use FPTS per GP"))))))))))))))))) -> 0.51874524 | AL174: =IFERROR(VLOOKUP(C174,CALC!$K$2:$M$8,2,FALSE),1) -> 1 | AM174: =IFERROR(VLOOKUP(C174,CALC!$K$2:$M$8,3,FALSE),1) -> 1 | AN174: =VLOOKUP(B174,CALC!$E$2:$H$33,3,FALSE) -> 0.9 | AO174: =VLOOKUP(B174,CALC!$E$2:$H$33,4,FALSE) -> 0.95 | AQ174: =$AA174*AM174 -> 5.4606667 | AR174: =$AA174*AL174 -> 5.4606667 | AS174: =$AA174*AO174 -> 5.1876333 | AT174: =$AA174*AN174 -> 4.9146 | AU174: =$AA174*AM174*AO174 -> 5.1876333 | AV174: =$AA174*AM174*AN174 -> 4.9146 | AW174: =$AA174*AL174*AO174 -> 5.1876333 | AX174: =$AA174*AL174*AN174 -> 4.9146 | AY174: =IF($C174="D",$AA174-$AE$3,$AA174-$AD$3) -> 0.54604762 | AZ174: =$AY174*AM174 -> 0.54604762 | BA174: =$AY174*AL174 -> 0.54604762 | BB174: =$AY174*AO174 -> 0.51874524 | BC174: =$AY174*AN174 -> 0.49144286 | BD174: =$AY174*AM174*AO174 -> 0.51874524 | BE174: =$AY174*AM174*AN174 -> 0.49144286 | BF174: =$AY174*AL174*AO174 -> 0.51874524 | BG174: =$AY174*AL174*AN174 -> 0.49144286
A175: Will Cuylle | B175: NYR | C175: =VLOOKUP(A175,CALC!$A$2:$C$494,3,FALSE) -> LW/RW | D175: 2 | E175: 84 | F175: 20.5 | G175: 16.4 | H175: 36.9 | I175: 6.7 | J175: 154.2 | K175: 308.6 | L175: 68.3 | M175: 57.8 | N175: 0.133 | O175: 16.5 | P175: =IF(F$4="Yes",F175*F$5,0) -> 102.5 | Q175: =IF(G$4="Yes",G175*G$5,0) -> 61.5 | R175: =IF(H$4="Yes",H175*H$5,0) -> 36.9 | S175: =IF(I$4="Yes",I175*I$5,0) -> 3.35 | T175: =IF(J$4="Yes",J175*J$5,0) -> 77.1 | U175: =IF(K$4="Yes",K175*K$5,0) -> 92.58 | V175: =IF(L$4="Yes",L175*L$5,0) -> 40.98 | W175: =IF(M$4="Yes",M175*M$5,0) -> 57.8 | ... Y175: =IF(O$4="Yes",O175*O$5,0) -> 0 | Z175: =SUM(P175:Y175) -> 472.843 | AA175: =Z175/E175 -> 5.6290833 | AB175: =IF(AND($P$3="Yes",$R$3="Full Effect",$U$3="Full Effect"),$BG175,IF(AND($P$3="Yes",$R$3="Medium Effect",$U$3="Full Effect"),$BE175,IF(AND($P$3="Yes",$R$3="Full Effect",$U$3="Medium Effect"),$BF175,IF(AND($P$3="Yes",$R$3="Medium Effect",$U$3="Medium Effect"),$BD175,IF(AND($P$3="Yes",$R$3="No Effect",$U$3="Medium Effect"),$BB175,IF(AND($P$3="Yes",$R$3="No Effect",$U$3="Full Effect"),$BC175,IF(AND($P$3="Yes",$R$3="Medium Effect",$U$3="No Effect"),$AZ175,IF(AND($P$3="Yes",$R$3="Full Effect",$U$3="No Effect"),$BA175,IF(AND($P$3="No",$R$3="Full Effect",$U$3="Full Effect"),$AX175,IF(AND($P$3="No",$R$3="Medium Effect",$U$3="Full Effect"),$AV175,IF(AND($P$3="No",$R$3="Full Effect",$U$3="Medium Effect"),$AW175,IF(AND($P$3="No",$R$3="Medium Effect",$U$3="Medium Effect"),$AU175,IF(AND($P$3="No",$R$3="No Effect",$U$3="Medium Effect"),$AS175,IF(AND($P$3="No",$R$3="No Effect",$U$3="Full Effect"),$AT175,IF(AND($P$3="No",$R$3="Medium Effect",$U$3="No Effect"),$AQ175,IF(AND($P$3="No",$R$3="Full Effect",$U$3="No Effect"),$AR175,IF(AND($P170="Yes",$R$3="No Effect",$U$3="No Effect"),$AY175,"Use FPTS per GP"))))))))))))))))) -> -0.14323474 | AL175: =IFERROR(VLOOKUP(C175,CALC!$K$2:$M$8,2,FALSE),1) -> 1.08 | AM175: =IFERROR(VLOOKUP(C175,CALC!$K$2:$M$8,3,FALSE),1) -> 1.04 | AN175: =VLOOKUP(B175,CALC!$E$2:$H$33,3,FALSE) -> 1.16 | AO175: =VLOOKUP(B175,CALC!$E$2:$H$33,4,FALSE) -> 1.08 | AQ175: =$AA175*AM175 -> 5.8542467 | AR175: =$AA175*AL175 -> 6.07941 | AS175: =$AA175*AO175 -> 6.07941 | AT175: =$AA175*AN175 -> 6.5297367 | AU175: =$AA175*AM175*AO175 -> 6.3225864 | AV175: =$AA175*AM175*AN175 -> 6.7909261 | AW175: =$AA175*AL175*AO175 -> 6.5657628 | AX175: =$AA175*AL175*AN175 -> 7.0521156 | AY175: =IF($C175="D",$AA175-$AE$3,$AA175-$AD$3) -> -0.12752381 | AZ175: =$AY175*AM175 -> -0.13262476 | BA175: =$AY175*AL175 -> -0.13772571 | BB175: =$AY175*AO175 -> -0.13772571 | BC175: =$AY175*AN175 -> -0.14792762 | BD175: =$AY175*AM175*AO175 -> -0.14323474 | BE175: =$AY175*AM175*AN175 -> -0.15384472 | BF175: =$AY175*AL175*AO175 -> -0.14874377 | BG175: =$AY175*AL175*AN175 -> -0.15976183
A176: Mackenzie Weegar | B176: UTA | C176: =VLOOKUP(A176,CALC!$A$2:$C$494,3,FALSE) -> D | D176: 2 | E176: 84 | F176: 5.9 | G176: 29.5 | H176: 35.4 | I176: 4.8 | J176: 149.4 | K176: 168.2 | L176: 180.6 | M176: 66.9 | N176: 0.039 | O176: 20.75 | P176: =IF(F$4="Yes",F176*F$5,0) -> 29.5 | Q176: =IF(G$4="Yes",G176*G$5,0) -> 110.625 | R176: =IF(H$4="Yes",H176*H$5,0) -> 35.4 | S176: =IF(I$4="Yes",I176*I$5,0) -> 2.4 | T176: =IF(J$4="Yes",J176*J$5,0) -> 74.7 | U176: =IF(K$4="Yes",K176*K$5,0) -> 50.46 | V176: =IF(L$4="Yes",L176*L$5,0) -> 108.36 | W176: =IF(M$4="Yes",M176*M$5,0) -> 66.9 | ... Y176: =IF(O$4="Yes",O176*O$5,0) -> 0 | Z176: =SUM(P176:Y176) -> 478.384 | AA176: =Z176/E176 -> 5.6950476 | AB176: =IF(AND($P$3="Yes",$R$3="Full Effect",$U$3="Full Effect"),$BG176,IF(AND($P$3="Yes",$R$3="Medium Effect",$U$3="Full Effect"),$BE176,IF(AND($P$3="Yes",$R$3="Full Effect",$U$3="Medium Effect"),$BF176,IF(AND($P$3="Yes",$R$3="Medium Effect",$U$3="Medium Effect"),$BD176,IF(AND($P$3="Yes",$R$3="No Effect",$U$3="Medium Effect"),$BB176,IF(AND($P$3="Yes",$R$3="No Effect",$U$3="Full Effect"),$BC176,IF(AND($P$3="Yes",$R$3="Medium Effect",$U$3="No Effect"),$AZ176,IF(AND($P$3="Yes",$R$3="Full Effect",$U$3="No Effect"),$BA176,IF(AND($P$3="No",$R$3="Full Effect",$U$3="Full Effect"),$AX176,IF(AND($P$3="No",$R$3="Medium Effect",$U$3="Full Effect"),$AV176,IF(AND($P$3="No",$R$3="Full Effect",$U$3="Medium Effect"),$AW176,IF(AND($P$3="No",$R$3="Medium Effect",$U$3="Medium Effect"),$AU176,IF(AND($P$3="No",$R$3="No Effect",$U$3="Medium Effect"),$AS176,IF(AND($P$3="No",$R$3="No Effect",$U$3="Full Effect"),$AT176,IF(AND($P$3="No",$R$3="Medium Effect",$U$3="No Effect"),$AQ176,IF(AND($P$3="No",$R$3="Full Effect",$U$3="No Effect"),$AR176,IF(AND($P171="Yes",$R$3="No Effect",$U$3="No Effect"),$AY176,"Use FPTS per GP"))))))))))))))))) -> 0.82725429 | AL176: =IFERROR(VLOOKUP(C176,CALC!$K$2:$M$8,2,FALSE),1) -> 1 | AM176: =IFERROR(VLOOKUP(C176,CALC!$K$2:$M$8,3,FALSE),1) -> 1 | AN176: =VLOOKUP(B176,CALC!$E$2:$H$33,3,FALSE) -> 1.12 | AO176: =VLOOKUP(B176,CALC!$E$2:$H$33,4,FALSE) -> 1.06 | AQ176: =$AA176*AM176 -> 5.6950476 | AR176: =$AA176*AL176 -> 5.6950476 | AS176: =$AA176*AO176 -> 6.0367505 | AT176: =$AA176*AN176 -> 6.3784533 | AU176: =$AA176*AM176*AO176 -> 6.0367505 | AV176: =$AA176*AM176*AN176 -> 6.3784533 | AW176: =$AA176*AL176*AO176 -> 6.0367505 | AX176: =$AA176*AL176*AN176 -> 6.3784533 | AY176: =IF($C176="D",$AA176-$AE$3,$AA176-$AD$3) -> 0.78042857 | AZ176: =$AY176*AM176 -> 0.78042857 | BA176: =$AY176*AL176 -> 0.78042857 | BB176: =$AY176*AO176 -> 0.82725429 | BC176: =$AY176*AN176 -> 0.87408 | BD176: =$AY176*AM176*AO176 -> 0.82725429 | BE176: =$AY176*AM176*AN176 -> 0.87408 | BF176: =$AY176*AL176*AO176 -> 0.82725429 | BG176: =$AY176*AL176*AN176 -> 0.87408
A177: Aliaksei Protas | B177: WSH | C177: =VLOOKUP(A177,CALC!$A$2:$C$494,3,FALSE) -> LW/RW | E177: 84 | F177: 27.6 | G177: 31 | H177: 58.6 | I177: 2.5 | J177: 169.1 | K177: 32.2 | L177: 42.7 | M177: 21 | N177: 0.163 | O177: 17.5 | P177: =IF(F$4="Yes",F177*F$5,0) -> 138 | Q177: =IF(G$4="Yes",G177*G$5,0) -> 116.25 | R177: =IF(H$4="Yes",H177*H$5,0) -> 58.6 | S177: =IF(I$4="Yes",I177*I$5,0) -> 1.25 | T177: =IF(J$4="Yes",J177*J$5,0) -> 84.55 | U177: =IF(K$4="Yes",K177*K$5,0) -> 9.66 | V177: =IF(L$4="Yes",L177*L$5,0) -> 25.62 | W177: =IF(M$4="Yes",M177*M$5,0) -> 21 | ... Y177: =IF(O$4="Yes",O177*O$5,0) -> 0 | Z177: =SUM(P177:Y177) -> 455.093 | AA177: =Z177/E177 -> 5.4177738 | AB177: =IF(AND($P$3="Yes",$R$3="Full Effect",$U$3="Full Effect"),$BG177,IF(AND($P$3="Yes",$R$3="Medium Effect",$U$3="Full Effect"),$BE177,IF(AND($P$3="Yes",$R$3="Full Effect",$U$3="Medium Effect"),$BF177,IF(AND($P$3="Yes",$R$3="Medium Effect",$U$3="Medium Effect"),$BD177,IF(AND($P$3="Yes",$R$3="No Effect",$U$3="Medium Effect"),$BB177,IF(AND($P$3="Yes",$R$3="No Effect",$U$3="Full Effect"),$BC177,IF(AND($P$3="Yes",$R$3="Medium Effect",$U$3="No Effect"),$AZ177,IF(AND($P$3="Yes",$R$3="Full Effect",$U$3="No Effect"),$BA177,IF(AND($P$3="No",$R$3="Full Effect",$U$3="Full Effect"),$AX177,IF(AND($P$3="No",$R$3="Medium Effect",$U$3="Full Effect"),$AV177,IF(AND($P$3="No",$R$3="Full Effect",$U$3="Medium Effect"),$AW177,IF(AND($P$3="No",$R$3="Medium Effect",$U$3="Medium Effect"),$AU177,IF(AND($P$3="No",$R$3="No Effect",$U$3="Medium Effect"),$AS177,IF(AND($P$3="No",$R$3="No Effect",$U$3="Full Effect"),$AT177,IF(AND($P$3="No",$R$3="Medium Effect",$U$3="No Effect"),$AQ177,IF(AND($P$3="No",$R$3="Full Effect",$U$3="No Effect"),$AR177,IF(AND($P172="Yes",$R$3="No Effect",$U$3="No Effect"),$AY177,"Use FPTS per GP"))))))))))))))))) -> -0.3858634 | AL177: =IFERROR(VLOOKUP(C177,CALC!$K$2:$M$8,2,FALSE),1) -> 1.08 | AM177: =IFERROR(VLOOKUP(C177,CALC!$K$2:$M$8,3,FALSE),1) -> 1.04 | AN177: =VLOOKUP(B177,CALC!$E$2:$H$33,3,FALSE) -> 1.19 | AO177: =VLOOKUP(B177,CALC!$E$2:$H$33,4,FALSE) -> 1.095 | AQ177: =$AA177*AM177 -> 5.6344848 | AR177: =$AA177*AL177 -> 5.8511957 | AS177: =$AA177*AO177 -> 5.9324623 | AT177: =$AA177*AN177 -> 6.4471508 | AU177: =$AA177*AM177*AO177 -> 6.1697608 | AV177: =$AA177*AM177*AN177 -> 6.7050369 | AW177: =$AA177*AL177*AO177 -> 6.4070593 | AX177: =$AA177*AL177*AN177 -> 6.9629229 | AY177: =IF($C177="D",$AA177-$AE$3,$AA177-$AD$3) -> -0.33883333 | AZ177: =$AY177*AM177 -> -0.35238667 | BA177: =$AY177*AL177 -> -0.36594 | BB177: =$AY177*AO177 -> -0.3710225 | BC177: =$AY177*AN177 -> -0.40321167 | BD177: =$AY177*AM177*AO177 -> -0.3858634 | BE177: =$AY177*AM177*AN177 -> -0.41934013 | BF177: =$AY177*AL177*AO177 -> -0.4007043 | BG177: =$AY177*AL177*AN177 -> -0.4354686
A178: Matt Duchene | B178: DAL | C178: =VLOOKUP(A178,CALC!$A$2:$C$494,3,FALSE) -> C/RW | D178: 2 | E178: 84 | F178: 24.3 | G178: 38.7 | H178: 63 | I178: 19.4 | J178: 140.3 | K178: 34.9 | L178: 29.9 | M178: 12 | N178: 0.173 | O178: 16.75 | P178: =IF(F$4="Yes",F178*F$5,0) -> 121.5 | Q178: =IF(G$4="Yes",G178*G$5,0) -> 145.125 | R178: =IF(H$4="Yes",H178*H$5,0) -> 63 | S178: =IF(I$4="Yes",I178*I$5,0) -> 9.7 | T178: =IF(J$4="Yes",J178*J$5,0) -> 70.15 | U178: =IF(K$4="Yes",K178*K$5,0) -> 10.47 | V178: =IF(L$4="Yes",L178*L$5,0) -> 17.94 | W178: =IF(M$4="Yes",M178*M$5,0) -> 12 | ... Y178: =IF(O$4="Yes",O178*O$5,0) -> 0 | Z178: =SUM(P178:Y178) -> 450.058 | AA178: =Z178/E178 -> 5.3578333 | AB178: =IF(AND($P$3="Yes",$R$3="Full Effect",$U$3="Full Effect"),$BG178,IF(AND($P$3="Yes",$R$3="Medium Effect",$U$3="Full Effect"),$BE178,IF(AND($P$3="Yes",$R$3="Full Effect",$U$3="Medium Effect"),$BF178,IF(AND($P$3="Yes",$R$3="Medium Effect",$U$3="Medium Effect"),$BD178,IF(AND($P$3="Yes",$R$3="No Effect",$U$3="Medium Effect"),$BB178,IF(AND($P$3="Yes",$R$3="No Effect",$U$3="Full Effect"),$BC178,IF(AND($P$3="Yes",$R$3="Medium Effect",$U$3="No Effect"),$AZ178,IF(AND($P$3="Yes",$R$3="Full Effect",$U$3="No Effect"),$BA178,IF(AND($P$3="No",$R$3="Full Effect",$U$3="Full Effect"),$AX178,IF(AND($P$3="No",$R$3="Medium Effect",$U$3="Full Effect"),$AV178,IF(AND($P$3="No",$R$3="Full Effect",$U$3="Medium Effect"),$AW178,IF(AND($P$3="No",$R$3="Medium Effect",$U$3="Medium Effect"),$AU178,IF(AND($P$3="No",$R$3="No Effect",$U$3="Medium Effect"),$AS178,IF(AND($P$3="No",$R$3="No Effect",$U$3="Full Effect"),$AT178,IF(AND($P$3="No",$R$3="Medium Effect",$U$3="No Effect"),$AQ178,IF(AND($P$3="No",$R$3="Full Effect",$U$3="No Effect"),$AR178,IF(AND($P173="Yes",$R$3="No Effect",$U$3="No Effect"),$AY178,"Use FPTS per GP"))))))))))))))))) -> -0.40878303 | AL178: =IFERROR(VLOOKUP(C178,CALC!$K$2:$M$8,2,FALSE),1) -> 1.01 | AM178: =IFERROR(VLOOKUP(C178,CALC!$K$2:$M$8,3,FALSE),1) -> 1.005 | AN178: =VLOOKUP(B178,CALC!$E$2:$H$33,3,FALSE) -> 1.04 | AO178: =VLOOKUP(B178,CALC!$E$2:$H$33,4,FALSE) -> 1.02 | AQ178: =$AA178*AM178 -> 5.3846225 | AR178: =$AA178*AL178 -> 5.4114117 | AS178: =$AA178*AO178 -> 5.46499 | AT178: =$AA178*AN178 -> 5.5721467 | AU178: =$AA178*AM178*AO178 -> 5.4923149 | AV178: =$AA178*AM178*AN178 -> 5.6000074 | AW178: =$AA178*AL178*AO178 -> 5.5196399 | AX178: =$AA178*AL178*AN178 -> 5.6278681 | AY178: =IF($C178="D",$AA178-$AE$3,$AA178-$AD$3) -> -0.39877381 | AZ178: =$AY178*AM178 -> -0.40076768 | BA178: =$AY178*AL178 -> -0.40276155 | BB178: =$AY178*AO178 -> -0.40674929 | BC178: =$AY178*AN178 -> -0.41472476 | BD178: =$AY178*AM178*AO178 -> -0.40878303 | BE178: =$AY178*AM178*AN178 -> -0.41679839 | BF178: =$AY178*AL178*AO178 -> -0.41081678 | BG178: =$AY178*AL178*AN178 -> -0.41887201
